File: wf_data/pub_366/DS0230/XRD.txt
[Measurement conditions]
Sample identification	Red
Comment - 1	"Configuration=Anton Paar XRK-900, Owner=User-1, Creation date=2/4/2004 2:42:16 PM"
Comment - 2	Goniometer=PW3050/60 (Theta/Theta); Minimum step size 2Theta:0.001; Minimum step size Omega:0.001
Comment - 3	Sample stage=Anton Paar XRK-900
Comment - 4	Diffractometer system=XPERT-PRO
Comment - 5	"Measurement program=Cristina_CO2, Owner=User-1, Creation date=9/11/2015 4:13:06 PM"
Anode material	Cu
K-Alpha1 wavelength	1.540598
K-Alpha2 wavelength	1.544426
Ratio K-Alpha2/K-Alpha1	0.5
Divergence slit	Fixed	0.76mm
Monochromator used	NO
Generator voltage	40
Tube current	40
File date and time	16/09/2015 04:57
Unit cell
h k l	 0 0 0
Temperature [K]	493
Scan axis	Gonio
Scan range	15	90.00017517
Scan step size	0.0167113
No. of points	4488
Scan type	CONTINUOUS
Time per step	99.695
[Scan points]
Angle	Intensity
15.00835563	566
15.05848944	597
15.10862324	593
15.15875705	650
15.20889086	636
15.25902467	591
15.30915847	557
15.35929228	610
15.40942609	629
15.45955989	574
15.5096937	574
15.55982751	571
15.60996131	603
15.66009512	584
15.71022893	584
15.76036273	653
15.81049654	599
15.86063035	594
15.91076416	586
15.96089796	591
16.01103177	604
16.06116558	616
16.11129938	536
16.16143319	607
16.211567	550
16.2617008	573
16.31183461	629
16.36196842	597
16.41210222	558
16.46223603	589
16.51236984	575
16.56250365	582
16.61263745	571
16.66277126	516
16.71290507	599
16.76303887	588
16.81317268	563
16.86330649	556
16.91344029	531
16.9635741	556
17.01370791	536
17.06384171	583
17.11397552	536
17.16410933	569
17.21424314	566
17.26437694	563
17.31451075	535
17.36464456	590
17.41477836	532
17.46491217	554
17.51504598	559
17.56517978	588
17.61531359	540
17.6654474	595
17.71558121	568
17.76571501	540
17.81584882	552
17.86598263	560
17.91611643	523
17.96625024	540
18.01638405	548
18.06651785	579
18.11665166	563
18.16678547	544
18.21691927	557
18.26705308	548
18.31718689	528
18.3673207	496
18.4174545	560
18.46758831	513
18.51772212	533
18.56785592	507
18.61798973	555
18.66812354	533
18.71825734	520
18.76839115	524
18.81852496	567
18.86865876	553
18.91879257	550
18.96892638	553
19.01906019	609
19.06919399	531
19.1193278	571
19.16946161	536
19.21959541	504
19.26972922	611
19.31986303	553
19.36999683	550
19.42013064	575
19.47026445	559
19.52039825	540
19.57053206	561
19.62066587	579
19.67079968	564
19.72093348	552
19.77106729	560
19.8212011	548
19.8713349	508
19.92146871	564
19.97160252	559
20.02173632	519
20.07187013	516
20.12200394	529
20.17213775	535
20.22227155	547
20.27240536	555
20.32253917	570
20.37267297	570
20.42280678	516
20.47294059	520
20.52307439	533
20.5732082	524
20.62334201	548
20.67347581	524
20.72360962	548
20.77374343	504
20.82387724	567
20.87401104	579
20.92414485	544
20.97427866	545
21.02441246	511
21.07454627	526
21.12468008	517
21.17481388	520
21.22494769	507
21.2750815	533
21.3252153	528
21.37534911	511
21.42548292	526
21.47561673	510
21.52575053	546
21.57588434	522
21.62601815	531
21.67615195	553
21.72628576	490
21.77641957	533
21.82655337	507
21.87668718	530
21.92682099	479
21.97695479	489
22.0270886	521
22.07722241	477
22.12735622	489
22.17749002	507
22.22762383	537
22.27775764	477
22.32789144	499
22.37802525	504
22.42815906	495
22.47829286	481
22.52842667	538
22.57856048	531
22.62869429	491
22.67882809	542
22.7289619	530
22.77909571	493
22.82922951	484
22.87936332	485
22.92949713	491
22.97963093	477
23.02976474	490
23.07989855	497
23.13003235	520
23.18016616	461
23.23029997	517
23.28043378	514
23.33056758	494
23.38070139	475
23.4308352	481
23.480969	484
23.53110281	554
23.58123662	513
23.63137042	503
23.68150423	499
23.73163804	522
23.78177184	459
23.83190565	509
23.88203946	524
23.93217327	520
23.98230707	479
24.03244088	492
24.08257469	475
24.13270849	505
24.1828423	489
24.23297611	493
24.28310991	498
24.33324372	493
24.38337753	464
24.43351133	529
24.48364514	504
24.53377895	510
24.58391276	498
24.63404656	468
24.68418037	466
24.73431418	506
24.78444798	485
24.83458179	490
24.8847156	508
24.9348494	520
24.98498321	466
25.03511702	478
25.08525083	493
25.13538463	520
25.18551844	542
25.23565225	527
25.28578605	477
25.33591986	520
25.38605367	492
25.43618747	522
25.48632128	501
25.53645509	519
25.58658889	509
25.6367227	507
25.68685651	510
25.73699032	519
25.78712412	512
25.83725793	499
25.88739174	516
25.93752554	511
25.98765935	470
26.03779316	491
26.08792696	505
26.13806077	483
26.18819458	537
26.23832838	500
26.28846219	532
26.338596	480
26.38872981	497
26.43886361	480
26.48899742	487
26.53913123	511
26.58926503	527
26.63939884	498
26.68953265	496
26.73966645	516
26.78980026	482
26.83993407	483
26.89006787	474
26.94020168	497
26.99033549	506
27.0404693	508
27.0906031	519
27.14073691	515
27.19087072	530
27.24100452	472
27.29113833	529
27.34127214	544
27.39140594	512
27.44153975	529
27.49167356	543
27.54180736	523
27.59194117	538
27.64207498	523
27.69220879	481
27.74234259	496
27.7924764	582
27.84261021	533
27.89274401	520
27.94287782	573
27.99301163	508
28.04314543	526
28.09327924	551
28.14341305	544
28.19354686	528
28.24368066	575
28.29381447	583
28.34394828	566
28.39408208	609
28.44421589	570
28.4943497	574
28.5444835	546
28.59461731	523
28.64475112	589
28.69488492	588
28.74501873	550
28.79515254	551
28.84528635	576
28.89542015	586
28.94555396	601
28.99568777	626
29.04582157	561
29.09595538	600
29.14608919	615
29.19622299	556
29.2463568	592
29.29649061	600
29.34662441	551
29.39675822	560
29.44689203	626
29.49702584	592
29.54715964	590
29.59729345	562
29.64742726	566
29.69756106	616
29.74769487	588
29.79782868	645
29.84796248	623
29.89809629	590
29.9482301	609
29.9983639	673
30.04849771	576
30.09863152	606
30.14876533	630
30.19889913	620
30.24903294	670
30.29916675	617
30.34930055	665
30.39943436	662
30.44956817	643
30.49970197	617
30.54983578	705
30.59996959	647
30.6501034	646
30.7002372	623
30.75037101	648
30.80050482	654
30.85063862	664
30.90077243	639
30.95090624	643
31.00104004	668
31.05117385	645
31.10130766	643
31.15144146	705
31.20157527	672
31.25170908	613
31.30184289	687
31.35197669	679
31.4021105	681
31.45224431	692
31.50237811	726
31.55251192	686
31.60264573	692
31.65277953	735
31.70291334	703
31.75304715	692
31.80318095	702
31.85331476	749
31.90344857	698
31.95358238	682
32.00371618	696
32.05384999	756
32.1039838	720
32.1541176	757
32.20425141	678
32.25438522	698
32.30451902	723
32.35465283	756
32.40478664	724
32.45492044	704
32.50505425	783
32.55518806	767
32.60532187	678
32.65545567	718
32.70558948	802
32.75572329	729
32.80585709	732
32.8559909	799
32.90612471	773
32.95625851	731
33.00639232	735
33.05652613	749
33.10665994	728
33.15679374	767
33.20692755	732
33.25706136	744
33.30719516	671
33.35732897	765
33.40746278	737
33.45759658	704
33.50773039	755
33.5578642	760
33.607998	725
33.65813181	726
33.70826562	720
33.75839943	724
33.80853323	713
33.85866704	701
33.90880085	662
33.95893465	720
34.00906846	788
34.05920227	725
34.10933607	775
34.15946988	737
34.20960369	734
34.25973749	725
34.3098713	755
34.36000511	745
34.41013892	741
34.46027272	744
34.51040653	725
34.56054034	730
34.61067414	776
34.66080795	682
34.71094176	728
34.76107556	720
34.81120937	781
34.86134318	732
34.91147698	779
34.96161079	763
35.0117446	783
35.06187841	791
35.11201221	804
35.16214602	821
35.21227983	723
35.26241363	740
35.31254744	770
35.36268125	794
35.41281505	775
35.46294886	812
35.51308267	837
35.56321648	834
35.61335028	809
35.66348409	836
35.7136179	840
35.7637517	836
35.81388551	829
35.86401932	807
35.91415312	843
35.96428693	833
36.01442074	888
36.06455454	859
36.11468835	854
36.16482216	927
36.21495597	934
36.26508977	885
36.31522358	858
36.36535739	903
36.41549119	920
36.465625	918
36.51575881	936
36.56589261	963
36.61602642	1020
36.66616023	899
36.71629403	937
36.76642784	982
36.81656165	1007
36.86669546	990
36.91682926	1001
36.96696307	1014
37.01709688	996
37.06723068	1019
37.11736449	1041
37.1674983	1014
37.2176321	1047
37.26776591	924
37.31789972	1006
37.36803352	1041
37.41816733	1013
37.46830114	1031
37.51843495	1014
37.56856875	1007
37.61870256	1008
37.66883637	1016
37.71897017	984
37.76910398	1069
37.81923779	1031
37.86937159	976
37.9195054	903
37.96963921	941
38.01977301	943
38.06990682	949
38.12004063	994
38.17017444	1001
38.22030824	925
38.27044205	963
38.32057586	945
38.37070966	1002
38.42084347	947
38.47097728	898
38.52111108	923
38.57124489	880
38.6213787	887
38.67151251	888
38.72164631	896
38.77178012	872
38.82191393	876
38.87204773	884
38.92218154	836
38.97231535	945
39.02244915	912
39.07258296	872
39.12271677	910
39.17285057	908
39.22298438	925
39.27311819	960
39.323252	955
39.3733858	944
39.42351961	972
39.47365342	993
39.52378722	979
39.57392103	1029
39.62405484	996
39.67418864	983
39.72432245	976
39.77445626	986
39.82459006	978
39.87472387	1027
39.92485768	1024
39.97499149	990
40.02512529	966
40.0752591	969
40.12539291	937
40.17552671	882
40.22566052	821
40.27579433	925
40.32592813	847
40.37606194	871
40.42619575	856
40.47632955	788
40.52646336	803
40.57659717	760
40.62673098	797
40.67686478	775
40.72699859	712
40.7771324	734
40.8272662	681
40.87740001	661
40.92753382	671
40.97766762	643
41.02780143	679
41.07793524	670
41.12806905	629
41.17820285	599
41.22833666	616
41.27847047	574
41.32860427	597
41.37873808	525
41.42887189	550
41.47900569	598
41.5291395	527
41.57927331	526
41.62940711	558
41.67954092	533
41.72967473	547
41.77980854	519
41.82994234	495
41.88007615	526
41.93020996	541
41.98034376	543
42.03047757	539
42.08061138	517
42.13074518	508
42.18087899	515
42.2310128	512
42.2811466	495
42.33128041	543
42.38141422	490
42.43154803	504
42.48168183	553
42.53181564	473
42.58194945	504
42.63208325	467
42.68221706	521
42.73235087	512
42.78248467	479
42.83261848	497
42.88275229	498
42.93288609	505
42.9830199	480
43.03315371	476
43.08328752	483
43.13342132	506
43.18355513	571
43.23368894	470
43.28382274	506
43.33395655	438
43.38409036	510
43.43422416	484
43.48435797	514
43.53449178	474
43.58462559	522
43.63475939	521
43.6848932	511
43.73502701	556
43.78516081	601
43.83529462	557
43.88542843	552
43.93556223	559
43.98569604	574
44.03582985	568
44.08596365	598
44.13609746	593
44.18623127	620
44.23636508	580
44.28649888	683
44.33663269	605
44.3867665	650
44.4369003	700
44.48703411	705
44.53716792	717
44.58730172	749
44.63743553	756
44.68756934	711
44.73770314	760
44.78783695	763
44.83797076	802
44.88810457	805
44.93823837	798
44.98837218	779
45.03850599	880
45.08863979	861
45.1387736	891
45.18890741	900
45.23904121	924
45.28917502	955
45.33930883	927
45.38944263	1018
45.43957644	975
45.48971025	967
45.53984406	1048
45.58997786	1065
45.64011167	1086
45.69024548	1023
45.74037928	1121
45.79051309	1058
45.8406469	1136
45.8907807	1134
45.94091451	1124
45.99104832	1152
46.04118213	1160
46.09131593	1135
46.14144974	1112
46.19158355	1088
46.24171735	1161
46.29185116	1151
46.34198497	1161
46.39211877	1132
46.44225258	1147
46.49238639	1090
46.54252019	1022
46.592654	1098
46.64278781	1035
46.69292162	1043
46.74305542	999
46.79318923	1015
46.84332304	950
46.89345684	938
46.94359065	919
46.99372446	907
47.04385826	865
47.09399207	821
47.14412588	752
47.19425968	794
47.24439349	772
47.2945273	708
47.34466111	658
47.39479491	661
47.44492872	655
47.49506253	569
47.54519633	622
47.59533014	593
47.64546395	558
47.69559775	580
47.74573156	523
47.79586537	504
47.84599917	509
47.89613298	527
47.94626679	508
47.9964006	457
48.0465344	492
48.09666821	463
48.14680202	475
48.19693582	443
48.24706963	437
48.29720344	415
48.34733724	427
48.39747105	390
48.44760486	403
48.49773866	456
48.54787247	426
48.59800628	383
48.64814009	429
48.69827389	386
48.7484077	409
48.79854151	399
48.84867531	368
48.89880912	396
48.94894293	387
48.99907673	409
49.04921054	393
49.09934435	372
49.14947816	393
49.19961196	390
49.24974577	352
49.29987958	354
49.35001338	378
49.40014719	372
49.450281	375
49.5004148	387
49.55054861	371
49.60068242	338
49.65081622	406
49.70095003	365
49.75108384	357
49.80121765	339
49.85135145	381
49.90148526	357
49.95161907	353
50.00175287	340
50.05188668	337
50.10202049	338
50.15215429	352
50.2022881	366
50.25242191	355
50.30255571	362
50.35268952	331
50.40282333	348
50.45295714	325
50.50309094	355
50.55322475	358
50.60335856	349
50.65349236	360
50.70362617	359
50.75375998	355
50.80389378	354
50.85402759	368
50.9041614	321
50.9542952	338
51.00442901	365
51.05456282	369
51.10469663	333
51.15483043	339
51.20496424	338
51.25509805	328
51.30523185	344
51.35536566	325
51.40549947	323
51.45563327	355
51.50576708	340
51.55590089	337
51.6060347	346
51.6561685	357
51.70630231	341
51.75643612	356
51.80656992	343
51.85670373	350
51.90683754	358
51.95697134	337
52.00710515	347
52.05723896	327
52.10737276	328
52.15750657	330
52.20764038	360
52.25777419	358
52.30790799	308
52.3580418	357
52.40817561	353
52.45830941	325
52.50844322	338
52.55857703	366
52.60871083	322
52.65884464	308
52.70897845	340
52.75911225	341
52.80924606	340
52.85937987	333
52.90951368	350
52.95964748	333
53.00978129	331
53.0599151	320
53.1100489	334
53.16018271	324
53.21031652	344
53.26045032	326
53.31058413	381
53.36071794	352
53.41085174	337
53.46098555	370
53.51111936	330
53.56125317	341
53.61138697	327
53.66152078	331
53.71165459	323
53.76178839	350
53.8119222	340
53.86205601	363
53.91218981	350
53.96232362	343
54.01245743	326
54.06259124	358
54.11272504	374
54.16285885	357
54.21299266	383
54.26312646	326
54.31326027	323
54.36339408	364
54.41352788	376
54.46366169	355
54.5137955	341
54.5639293	319
54.61406311	319
54.66419692	326
54.71433073	353
54.76446453	355
54.81459834	336
54.86473215	357
54.91486595	341
54.96499976	343
55.01513357	347
55.06526737	369
55.11540118	323
55.16553499	337
55.21566879	331
55.2658026	321
55.31593641	359
55.36607022	366
55.41620402	365
55.46633783	370
55.51647164	341
55.56660544	340
55.61673925	325
55.66687306	344
55.71700686	347
55.76714067	327
55.81727448	335
55.86740828	360
55.91754209	404
55.9676759	320
56.01780971	336
56.06794351	348
56.11807732	375
56.16821113	370
56.21834493	338
56.26847874	336
56.31861255	347
56.36874635	336
56.41888016	382
56.46901397	366
56.51914778	379
56.56928158	365
56.61941539	370
56.6695492	354
56.719683	331
56.76981681	365
56.81995062	429
56.87008442	378
56.92021823	376
56.97035204	383
57.02048584	387
57.07061965	363
57.12075346	393
57.17088727	349
57.22102107	372
57.27115488	385
57.32128869	410
57.37142249	347
57.4215563	375
57.47169011	362
57.52182391	364
57.57195772	398
57.62209153	397
57.67222533	390
57.72235914	397
57.77249295	381
57.82262676	391
57.87276056	369
57.92289437	376
57.97302818	396
58.02316198	370
58.07329579	394
58.1234296	374
58.1735634	396
58.22369721	438
58.27383102	395
58.32396482	403
58.37409863	416
58.42423244	414
58.47436625	429
58.52450005	405
58.57463386	414
58.62476767	421
58.67490147	446
58.72503528	419
58.77516909	410
58.82530289	429
58.8754367	418
58.92557051	443
58.97570431	407
59.02583812	437
59.07597193	458
59.12610574	454
59.17623954	457
59.22637335	417
59.27650716	427
59.32664096	472
59.37677477	423
59.42690858	456
59.47704238	468
59.52717619	419
59.57731	447
59.62744381	462
59.67757761	454
59.72771142	483
59.77784523	463
59.82797903	458
59.87811284	453
59.92824665	454
59.97838045	469
60.02851426	472
60.07864807	491
60.12878187	496
60.17891568	453
60.22904949	458
60.2791833	446
60.3293171	463
60.37945091	461
60.42958472	475
60.47971852	466
60.52985233	482
60.57998614	497
60.63011994	462
60.68025375	468
60.73038756	508
60.78052136	464
60.83065517	481
60.88078898	510
60.93092279	527
60.98105659	499
61.0311904	504
61.08132421	528
61.13145801	442
61.18159182	465
61.23172563	504
61.28185943	510
61.33199324	485
61.38212705	524
61.43226085	464
61.48239466	492
61.53252847	527
61.58266228	492
61.63279608	459
61.68292989	489
61.7330637	474
61.7831975	475
61.83333131	481
61.88346512	481
61.93359892	483
61.98373273	487
62.03386654	495
62.08400035	452
62.13413415	500
62.18426796	458
62.23440177	453
62.28453557	477
62.33466938	474
62.38480319	463
62.43493699	503
62.4850708	450
62.53520461	462
62.58533841	461
62.63547222	461
62.68560603	468
62.73573984	479
62.78587364	472
62.83600745	430
62.88614126	454
62.93627506	468
62.98640887	483
63.03654268	458
63.08667648	429
63.13681029	453
63.1869441	404
63.2370779	436
63.28721171	480
63.33734552	445
63.38747933	450
63.43761313	493
63.48774694	470
63.53788075	461
63.58801455	448
63.63814836	472
63.68828217	469
63.73841597	454
63.78854978	406
63.83868359	521
63.88881739	460
63.9389512	467
63.98908501	457
64.03921882	508
64.08935262	452
64.13948643	509
64.18962024	480
64.23975404	511
64.28988785	508
64.34002166	543
64.39015546	529
64.44028927	509
64.49042308	520
64.54055689	533
64.59069069	538
64.6408245	532
64.69095831	537
64.74109211	559
64.79122592	593
64.84135973	589
64.89149353	583
64.94162734	572
64.99176115	609
65.04189495	611
65.09202876	594
65.14216257	607
65.19229638	635
65.24243018	655
65.29256399	643
65.3426978	653
65.3928316	707
65.44296541	720
65.49309922	731
65.54323302	747
65.59336683	843
65.64350064	830
65.69363444	793
65.74376825	805
65.79390206	884
65.84403587	869
65.89416967	919
65.94430348	982
65.99443729	976
66.04457109	995
66.0947049	1045
66.14483871	1037
66.19497251	1102
66.24510632	1127
66.29524013	1175
66.34537393	1226
66.39550774	1222
66.44564155	1241
66.49577536	1295
66.54590916	1223
66.59604297	1286
66.64617678	1228
66.69631058	1273
66.74644439	1268
66.7965782	1284
66.846712	1297
66.89684581	1202
66.94697962	1260
66.99711343	1262
67.04724723	1283
67.09738104	1247
67.14751485	1190
67.19764865	1173
67.24778246	1187
67.29791627	1158
67.34805007	1183
67.39818388	1066
67.44831769	1180
67.49845149	1142
67.5485853	1095
67.59871911	1039
67.64885292	1042
67.69898672	1029
67.74912053	1024
67.79925434	955
67.84938814	947
67.89952195	921
67.94965576	839
67.99978956	935
68.04992337	806
68.10005718	830
68.15019098	773
68.20032479	790
68.2504586	793
68.30059241	793
68.35072621	725
68.40086002	669
68.45099383	649
68.50112763	677
68.55126144	652
68.60139525	599
68.65152905	610
68.70166286	572
68.75179667	577
68.80193047	532
68.85206428	552
68.90219809	557
68.9523319	466
69.0024657	510
69.05259951	488
69.10273332	509
69.15286712	440
69.20300093	451
69.25313474	472
69.30326854	434
69.35340235	450
69.40353616	409
69.45366996	415
69.50380377	421
69.55393758	406
69.60407139	388
69.65420519	383
69.704339	398
69.75447281	340
69.80460661	400
69.85474042	374
69.90487423	359
69.95500803	331
70.00514184	350
70.05527565	350
70.10540946	331
70.15554326	358
70.20567707	368
70.25581088	379
70.30594468	348
70.35607849	371
70.4062123	317
70.4563461	333
70.50647991	367
70.55661372	362
70.60674752	339
70.65688133	316
70.70701514	319
70.75714895	312
70.80728275	304
70.85741656	322
70.90755037	372
70.95768417	316
71.00781798	327
71.05795179	332
71.10808559	337
71.1582194	258
71.20835321	315
71.25848701	351
71.30862082	357
71.35875463	326
71.40888844	293
71.45902224	288
71.50915605	297
71.55928986	327
71.60942366	324
71.65955747	297
71.70969128	257
71.75982508	287
71.80995889	316
71.8600927	307
71.9102265	315
71.96036031	284
72.01049412	339
72.06062793	262
72.11076173	313
72.16089554	310
72.21102935	292
72.26116315	302
72.31129696	287
72.36143077	296
72.41156457	317
72.46169838	269
72.51183219	283
72.561966	290
72.6120998	262
72.66223361	285
72.71236742	255
72.76250122	297
72.81263503	280
72.86276884	300
72.91290264	304
72.96303645	268
73.01317026	278
73.06330406	315
73.11343787	283
73.16357168	270
73.21370549	293
73.26383929	286
73.3139731	277
73.36410691	294
73.41424071	271
73.46437452	294
73.51450833	262
73.56464213	277
73.61477594	250
73.66490975	253
73.71504355	296
73.76517736	276
73.81531117	291
73.86544498	299
73.91557878	301
73.96571259	285
74.0158464	313
74.0659802	273
74.11611401	268
74.16624782	284
74.21638162	296
74.26651543	295
74.31664924	275
74.36678304	310
74.41691685	273
74.46705066	269
74.51718447	309
74.56731827	261
74.61745208	318
74.66758589	275
74.71771969	287
74.7678535	303
74.81798731	275
74.86812111	264
74.91825492	279
74.96838873	296
75.01852254	274
75.06865634	270
75.11879015	271
75.16892396	283
75.21905776	276
75.26919157	284
75.31932538	288
75.36945918	281
75.41959299	272
75.4697268	264
75.5198606	286
75.56999441	284
75.62012822	313
75.67026203	276
75.72039583	308
75.77052964	295
75.82066345	281
75.87079725	273
75.92093106	292
75.97106487	275
76.02119867	265
76.07133248	250
76.12146629	247
76.17160009	288
76.2217339	285
76.27186771	258
76.32200152	279
76.37213532	285
76.42226913	260
76.47240294	299
76.52253674	275
76.57267055	276
76.62280436	308
76.67293816	276
76.72307197	287
76.77320578	289
76.82333958	280
76.87347339	304
76.9236072	271
76.97374101	275
77.02387481	272
77.07400862	252
77.12414243	263
77.17427623	285
77.22441004	285
77.27454385	277
77.32467765	260
77.37481146	264
77.42494527	306
77.47507908	286
77.52521288	276
77.57534669	264
77.6254805	266
77.6756143	260
77.72574811	304
77.77588192	299
77.82601572	301
77.87614953	284
77.92628334	272
77.97641714	241
78.02655095	270
78.07668476	238
78.12681857	262
78.17695237	280
78.22708618	274
78.27721999	252
78.32735379	245
78.3774876	285
78.42762141	279
78.47775521	258
78.52788902	285
78.57802283	249
78.62815663	264
78.67829044	281
78.72842425	278
78.77855806	257
78.82869186	244
78.87882567	288
78.92895948	258
78.97909328	266
79.02922709	271
79.0793609	259
79.1294947	255
79.17962851	286
79.22976232	284
79.27989612	289
79.33002993	281
79.38016374	289
79.43029755	280
79.48043135	246
79.53056516	250
79.58069897	252
79.63083277	260
79.68096658	277
79.73110039	252
79.78123419	259
79.831368	256
79.88150181	279
79.93163561	278
79.98176942	248
80.03190323	264
80.08203704	248
80.13217084	274
80.18230465	240
80.23243846	252
80.28257226	249
80.33270607	269
80.38283988	253
80.43297368	271
80.48310749	237
80.5332413	240
80.58337511	231
80.63350891	250
80.68364272	240
80.73377653	249
80.78391033	240
80.83404414	256
80.88417795	265
80.93431175	252
80.98444556	258
81.03457937	233
81.08471317	228
81.13484698	257
81.18498079	230
81.2351146	261
81.2852484	258
81.33538221	237
81.38551602	260
81.43564982	258
81.48578363	240
81.53591744	275
81.58605124	244
81.63618505	276
81.68631886	263
81.73645266	262
81.78658647	253
81.83672028	293
81.88685409	270
81.93698789	280
81.9871217	296
82.03725551	281
82.08738931	266
82.13752312	240
82.18765693	247
82.23779073	247
82.28792454	243
82.33805835	289
82.38819215	284
82.43832596	270
82.48845977	264
82.53859358	281
82.58872738	259
82.63886119	271
82.688995	253
82.7391288	259
82.78926261	232
82.83939642	266
82.88953022	231
82.93966403	253
82.98979784	223
83.03993165	268
83.09006545	261
83.14019926	261
83.19033307	260
83.24046687	248
83.29060068	257
83.34073449	255
83.39086829	266
83.4410021	284
83.49113591	274
83.54126971	234
83.59140352	262
83.64153733	250
83.69167114	248
83.74180494	242
83.79193875	245
83.84207256	257
83.89220636	242
83.94234017	288
83.99247398	278
84.04260778	215
84.09274159	259
84.1428754	275
84.1930092	264
84.24314301	291
84.29327682	276
84.34341063	256
84.39354443	259
84.44367824	265
84.49381205	272
84.54394585	249
84.59407966	244
84.64421347	270
84.69434727	286
84.74448108	308
84.79461489	301
84.84474869	273
84.8948825	281
84.94501631	278
84.99515012	305
85.04528392	307
85.09541773	283
85.14555154	285
85.19568534	290
85.24581915	280
85.29595296	285
85.34608676	293
85.39622057	290
85.44635438	256
85.49648819	266
85.54662199	274
85.5967558	270
85.64688961	278
85.69702341	266
85.74715722	243
85.79729103	274
85.84742483	283
85.89755864	214
85.94769245	228
85.99782625	206
86.04796006	261
86.09809387	245
86.14822768	243
86.19836148	269
86.24849529	240
86.2986291	255
86.3487629	230
86.39889671	242
86.44903052	237
86.49916432	239
86.54929813	217
86.59943194	237
86.64956574	243
86.69969955	229
86.74983336	222
86.79996717	231
86.85010097	240
86.90023478	232
86.95036859	224
87.00050239	228
87.0506362	236
87.10077001	218
87.15090381	233
87.20103762	230
87.25117143	232
87.30130523	222
87.35143904	212
87.40157285	237
87.45170666	222
87.50184046	205
87.55197427	193
87.60210808	215
87.65224188	206
87.70237569	210
87.7525095	197
87.8026433	199
87.85277711	198
87.90291092	220
87.95304473	183
88.00317853	198
88.05331234	216
88.10344615	206
88.15357995	171
88.20371376	200
88.25384757	223
88.30398137	208
88.35411518	202
88.40424899	209
88.45438279	240
88.5045166	202
88.55465041	205
88.60478422	233
88.65491802	216
88.70505183	195
88.75518564	196
88.80531944	190
88.85545325	202
88.90558706	198
88.95572086	228
89.00585467	205
89.05598848	194
89.10612228	202
89.15625609	207
89.2063899	211
89.25652371	213
89.30665751	205
89.35679132	195
89.40692513	186
89.45705893	198
89.50719274	199
89.55732655	224
89.60746035	194
89.65759416	205
89.70772797	193
89.75786177	180
89.80799558	196
89.85812939	228
89.9082632	208
89.958397	202
89.99181954	222